
Waiting for JIT...
Traceback (most recent call last):
  File "/home/pedro/PINN/jaxpi/examples/geomII/main.py", line 39, in <module>
    app.run(main)
  File "/usr/local/lib/python3.11/dist-packages/absl/app.py", line 308, in run
    _run_main(main, args)
  File "/usr/local/lib/python3.11/dist-packages/absl/app.py", line 254, in _run_main
    sys.exit(main(argv))
             ^^^^^^^^^^
  File "/home/pedro/PINN/jaxpi/examples/geomII/main.py", line 31, in main
    train.train_and_evaluate(FLAGS.config, FLAGS.workdir)
  File "/home/pedro/PINN/jaxpi/examples/geomII/train.py", line 109, in train_and_evaluate
    model.state = model.step(model.state, batch)
                  ^^^^^^^^^^^^^^^^^^^^^^^^^^^^^^
  File "/usr/local/lib/python3.11/dist-packages/jaxpi/models.py", line 171, in step
    grads = grad(self.loss)(state.params, state.weights, batch, *args)
            ^^^^^^^^^^^^^^^^^^^^^^^^^^^^^^^^^^^^^^^^^^^^^^^^^^^^^^^^^^
  File "/usr/local/lib/python3.11/dist-packages/jaxpi/models.py", line 124, in loss
    losses = self.losses(params, batch, *args)
             ^^^^^^^^^^^^^^^^^^^^^^^^^^^^^^^^^
  File "/home/pedro/PINN/jaxpi/examples/geomII/models.py", line 166, in losses
    ru_pred, rv_pred, rc_pred = self.r_pred_fn(
    ^^^^^^^^^^^^^^^^^^^^^^^^^
ValueError: too many values to unpack (expected 3)
--------------------
For simplicity, JAX has removed its internal frames from the traceback of the following exception. Set JAX_TRACEBACK_FILTERING=off to include these.