
Waiting for JIT...
Traceback (most recent call last):
  File "/usr/local/lib/python3.11/dist-packages/jax/_src/lax/lax.py", line 149, in broadcast_shapes
    return _broadcast_shapes_cached(*shapes)
           ^^^^^^^^^^^^^^^^^^^^^^^^^^^^^^^^^
  File "/usr/local/lib/python3.11/dist-packages/jax/_src/util.py", line 290, in wrapper
    return cached(config.trace_context(), *args, **kwargs)
           ^^^^^^^^^^^^^^^^^^^^^^^^^^^^^^^^^^^^^^^^^^^^^^^
  File "/usr/local/lib/python3.11/dist-packages/jax/_src/util.py", line 283, in cached
    return f(*args, **kwargs)
           ^^^^^^^^^^^^^^^^^^
  File "/usr/local/lib/python3.11/dist-packages/jax/_src/lax/lax.py", line 155, in _broadcast_shapes_cached
    return _broadcast_shapes_uncached(*shapes)
           ^^^^^^^^^^^^^^^^^^^^^^^^^^^^^^^^^^^
  File "/usr/local/lib/python3.11/dist-packages/jax/_src/lax/lax.py", line 171, in _broadcast_shapes_uncached
    raise ValueError(f"Incompatible shapes for broadcasting: shapes={list(shapes)}")
ValueError: Incompatible shapes for broadcasting: shapes=[(57,), (57, 2)]
During handling of the above exception, another exception occurred:
Traceback (most recent call last):
  File "/home/pedro/PINN/jaxpi/examples/geomII/main.py", line 39, in <module>
    app.run(main)
  File "/usr/local/lib/python3.11/dist-packages/absl/app.py", line 308, in run
    _run_main(main, args)
  File "/usr/local/lib/python3.11/dist-packages/absl/app.py", line 254, in _run_main
    sys.exit(main(argv))
             ^^^^^^^^^^
  File "/home/pedro/PINN/jaxpi/examples/geomII/main.py", line 31, in main
    train.train_and_evaluate(FLAGS.config, FLAGS.workdir)
  File "/home/pedro/PINN/jaxpi/examples/geomII/train.py", line 108, in train_and_evaluate
    model.state = model.step(model.state, batch)
                  ^^^^^^^^^^^^^^^^^^^^^^^^^^^^^^
  File "/usr/local/lib/python3.11/dist-packages/jaxpi/models.py", line 171, in step
    grads = grad(self.loss)(state.params, state.weights, batch, *args)
            ^^^^^^^^^^^^^^^^^^^^^^^^^^^^^^^^^^^^^^^^^^^^^^^^^^^^^^^^^^
  File "/usr/local/lib/python3.11/dist-packages/jaxpi/models.py", line 124, in loss
    losses = self.losses(params, batch, *args)
             ^^^^^^^^^^^^^^^^^^^^^^^^^^^^^^^^^
  File "/home/pedro/PINN/jaxpi/examples/geomII/models.py", line 136, in losses
    p_in_loss = jnp.mean((p_in_pred - self.p_in) ** 2)
                          ~~~~~~~~~~^~~~~~~~~~~
  File "/usr/local/lib/python3.11/dist-packages/jax/_src/numpy/array_methods.py", line 736, in op
    return getattr(self.aval, f"_{name}")(self, *args)
           ^^^^^^^^^^^^^^^^^^^^^^^^^^^^^^^^^^^^^^^^^^^
  File "/usr/local/lib/python3.11/dist-packages/jax/_src/numpy/array_methods.py", line 264, in deferring_binary_op
    return binary_op(*args)
           ^^^^^^^^^^^^^^^^
  File "/usr/local/lib/python3.11/dist-packages/jax/_src/numpy/ufuncs.py", line 85, in <lambda>
    fn = lambda x1, x2, /: lax_fn(*promote_args(numpy_fn.__name__, x1, x2))
                                   ^^^^^^^^^^^^^^^^^^^^^^^^^^^^^^^^^^^^^^^
  File "/usr/local/lib/python3.11/dist-packages/jax/_src/numpy/util.py", line 381, in promote_args
    return promote_shapes(fun_name, *promote_dtypes(*args))
           ^^^^^^^^^^^^^^^^^^^^^^^^^^^^^^^^^^^^^^^^^^^^^^^^
  File "/usr/local/lib/python3.11/dist-packages/jax/_src/numpy/util.py", line 250, in promote_shapes
    result_rank = len(lax.broadcast_shapes(*shapes))
                      ^^^^^^^^^^^^^^^^^^^^^^^^^^^^^
ValueError: Incompatible shapes for broadcasting: shapes=[(57,), (57, 2)]
--------------------
For simplicity, JAX has removed its internal frames from the traceback of the following exception. Set JAX_TRACEBACK_FILTERING=off to include these.