u: 1.5128872107779776 - -0.061359723383504226
v: 0.7649866773596693 - -0.3430998289769446
p: 7421.404622109959 - -185.64831724525706
Traceback (most recent call last):
  File "/home/pedro/PINN/jaxpi/examples/geomIII2/main.py", line 39, in <module>
    app.run(main)
  File "/usr/local/lib/python3.11/dist-packages/absl/app.py", line 308, in run
    _run_main(main, args)
  File "/usr/local/lib/python3.11/dist-packages/absl/app.py", line 254, in _run_main
    sys.exit(main(argv))
             ^^^^^^^^^^
  File "/home/pedro/PINN/jaxpi/examples/geomIII2/main.py", line 31, in main
    train.train_and_evaluate(FLAGS.config, FLAGS.workdir)
  File "/home/pedro/PINN/jaxpi/examples/geomIII2/train.py", line 46, in train_and_evaluate
    ) = get_dataset()
        ^^^^^^^^^^^^^
  File "/home/pedro/PINN/jaxpi/examples/geomIII2/utils.py", line 69, in get_dataset
    u_fem, v_fem, p_fem, coords_fem = get_fem_data()
                                      ^^^^^^^^^^^^^^
  File "/home/pedro/PINN/jaxpi/examples/geomIII2/utils.py", line 29, in get_fem_data
    print(dassdaq)
          ^^^^^^^
NameError: name 'dassdaq' is not defined